<?xml version="1.0"?>
<robot name="/Users/sam/Develop/lgdxrobot2-webots/LGDXRobot2.urdf" xmlns:xacro="http://ros.org/wiki/xacro">
  <link name="base_link">
  </link>
  <joint name="wheel4" type="continuous">
    <parent link="base_link"/>
    <child link="WHEEL_4_SOLID"/>
    <axis xyz="0 -0.000004 -1"/>
    <limit effort="10" velocity="10"/>
    <origin xyz="-0.1055 -0.1025 0.0375" rpy="1.5708 0 0"/>
  </joint>
  <link name="WHEEL_4_SOLID">
    <visual>
      <origin xyz="0 0 0" rpy="0 0 0"/>
      <geometry>
        <cylinder radius="0.0375" length="0.032"/>
      </geometry>
    </visual>
    <collision>
      <origin xyz="0 0 0" rpy="0 0 0"/>
      <geometry>
        <cylinder radius="0.0375" length="0.032"/>
      </geometry>
    </collision>
  </link>
  <joint name="wheel3" type="continuous">
    <parent link="base_link"/>
    <child link="WHEEL_3_SOLID"/>
    <axis xyz="0 -0.000004 -1"/>
    <limit effort="10" velocity="10"/>
    <origin xyz="-0.1055 0.1025 0.0375" rpy="1.5708 0 0"/>
  </joint>
  <link name="WHEEL_3_SOLID">
    <visual>
      <origin xyz="0 0 0" rpy="0 0 0"/>
      <geometry>
        <cylinder radius="0.0375" length="0.032"/>
      </geometry>
    </visual>
    <collision>
      <origin xyz="0 0 0" rpy="0 0 0"/>
      <geometry>
        <cylinder radius="0.0375" length="0.032"/>
      </geometry>
    </collision>
  </link>
  <joint name="wheel2" type="continuous">
    <parent link="base_link"/>
    <child link="WHEEL_2_SOLID"/>
    <axis xyz="0 -0.000004 -1"/>
    <limit effort="10" velocity="10"/>
    <origin xyz="0.1055 -0.1025 0.0375" rpy="1.5708 0 0"/>
  </joint>
  <link name="WHEEL_2_SOLID">
    <visual>
      <origin xyz="0 0 0" rpy="0 0 0"/>
      <geometry>
        <cylinder radius="0.0375" length="0.032"/>
      </geometry>
    </visual>
    <collision>
      <origin xyz="0 0 0" rpy="0 0 0"/>
      <geometry>
        <cylinder radius="0.0375" length="0.032"/>
      </geometry>
    </collision>
  </link>
  <joint name="wheel1" type="continuous">
    <parent link="base_link"/>
    <child link="WHEEL_1_SOLID"/>
    <axis xyz="0 -0.000004 -1"/>
    <limit effort="10" velocity="10"/>
    <origin xyz="0.1055 0.1025 0.0375" rpy="1.5708 0 0"/>
  </joint>
  <link name="WHEEL_1_SOLID">
    <visual>
      <origin xyz="0 0 0" rpy="0 0 0"/>
      <geometry>
        <cylinder radius="0.0375" length="0.032"/>
      </geometry>
    </visual>
    <collision>
      <origin xyz="0 0 0" rpy="0 0 0"/>
      <geometry>
        <cylinder radius="0.0375" length="0.032"/>
      </geometry>
    </collision>
  </link>
  <link name="BASE_FRONT_SOLID">
    <visual>
      <origin xyz="0 0 0" rpy="0 0 0"/>
      <geometry>
        <box size="0.08 0.145 0.004"/>
      </geometry>
    </visual>
    <collision>
      <origin xyz="0 0 0" rpy="0 0 0"/>
      <geometry>
        <box size="0.08 0.145 0.004"/>
      </geometry>
    </collision>
  </link>
  <joint name="base_link_BASE_FRONT_SOLID_joint" type="fixed">
    <parent link="base_link"/>
    <child link="BASE_FRONT_SOLID"/>
    <origin xyz="0.102 0 0.057" rpy="0 0 0"/>
  </joint>
  <link name="BASE_REAR_SOLID">
    <visual>
      <geometry>
        <box size="0.08 0.145 0.004"/>
      </geometry>
    </visual>
    <collision>
      <geometry>
        <box size="0.08 0.145 0.004"/>
      </geometry>
    </collision>
  </link>
  <joint name="base_link_BASE_REAR_SOLID_joint" type="fixed">
    <parent link="base_link"/>
    <child link="BASE_REAR_SOLID"/>
    <origin xyz="-0.102 0 0.057" rpy="0 0 0"/>
  </joint>
  <link name="BASE_TOP_SOLID">
    <visual>
      <geometry>
        <box size="0.286 0.237 0.004"/>
      </geometry>
    </visual>
    <collision>
      <geometry>
        <box size="0.286 0.237 0.004"/>
      </geometry>
    </collision>
  </link>
  <joint name="base_link_BASE_TOP_SOLID_joint" type="fixed">
    <parent link="base_link"/>
    <child link="BASE_TOP_SOLID"/>
    <origin xyz="0 0 0.129" rpy="0 0 0"/>
  </joint>
  <link name="BASE_CENTRE_SOLID">
    <visual>
      <geometry>
        <box size="0.124 0.237 0.004"/>
      </geometry>
    </visual>
    <collision>
      <geometry>
        <box size="0.124 0.237 0.004"/>
      </geometry>
    </collision>
  </link>
  <joint name="base_link_BASE_CENTRE_SOLID_joint" type="fixed">
    <parent link="base_link"/>
    <child link="BASE_CENTRE_SOLID"/>
    <origin xyz="0 0 0.057" rpy="0 0 0"/>
  </joint>
  <link name="lidar">
    <visual>
      <origin xyz="0.014 0 -0.014" rpy="1.5708 0.00001 -1.5708"/>
      <geometry>
        <box size="0.07 0.01 0.1"/>
      </geometry>
    </visual>
    <collision>
      <origin xyz="0.014 0 -0.014" rpy="1.5708 0.00001 -1.5708"/>
      <geometry>
        <box size="0.07 0.01 0.1"/>
      </geometry>
    </collision>
    <visual>
      <origin xyz="0 0 0" rpy="0 0 0"/>
      <geometry>
        <cylinder radius="0.032" length="0.021"/>
      </geometry>
    </visual>
    <collision>
      <origin xyz="0 0 0" rpy="0 0 0"/>
      <geometry>
        <cylinder radius="0.032" length="0.021"/>
      </geometry>
    </collision>
  </link>
  <joint name="base_link_lidar_joint" type="fixed">
    <parent link="base_link"/>
    <child link="lidar"/>
    <origin xyz="0 0 0.157" rpy="0 0 3.14159"/>
  </joint>
  <link name="screw3">
    <visual>
      <origin xyz="0.01 0 0" rpy="3.141593 1.570793 3.141593"/>
      <geometry>
        <cylinder radius="0.0015" length="0.02"/>
      </geometry>
    </visual>
    <collision>
      <origin xyz="0.01 0 0" rpy="3.141593 1.570793 3.141593"/>
      <geometry>
        <cylinder radius="0.0015" length="0.02"/>
      </geometry>
    </collision>
    <visual>
      <origin xyz="-0.0015 0 0" rpy="3.141593 1.570793 3.141593"/>
      <geometry>
        <cylinder radius="0.0025" length="0.003"/>
      </geometry>
    </visual>
    <collision>
      <origin xyz="-0.0015 0 0" rpy="3.141593 1.570793 3.141593"/>
      <geometry>
        <cylinder radius="0.0025" length="0.003"/>
      </geometry>
    </collision>
  </link>
  <joint name="lidar_screw3_joint" type="fixed">
    <parent link="lidar"/>
    <child link="screw3"/>
    <origin xyz="0.035 0.0245 -0.0105" rpy="0 1.570787 0"/>
  </joint>
  <link name="screw2">
    <visual>
      <origin xyz="0.01 0 0" rpy="3.141593 1.570793 3.141593"/>
      <geometry>
        <cylinder radius="0.0015" length="0.02"/>
      </geometry>
    </visual>
    <collision>
      <origin xyz="0.01 0 0" rpy="3.141593 1.570793 3.141593"/>
      <geometry>
        <cylinder radius="0.0015" length="0.02"/>
      </geometry>
    </collision>
    <visual>
      <origin xyz="-0.0015 0 0" rpy="3.141593 1.570793 3.141593"/>
      <geometry>
        <cylinder radius="0.0025" length="0.003"/>
      </geometry>
    </visual>
    <collision>
      <origin xyz="-0.0015 0 0" rpy="3.141593 1.570793 3.141593"/>
      <geometry>
        <cylinder radius="0.0025" length="0.003"/>
      </geometry>
    </collision>
  </link>
  <joint name="lidar_screw2_joint" type="fixed">
    <parent link="lidar"/>
    <child link="screw2"/>
    <origin xyz="0.035 0.0245 -0.0105" rpy="0 1.570787 0"/>
  </joint>
  <link name="screw1">
    <visual>
      <origin xyz="0.01 0 0" rpy="3.141593 1.570793 3.141593"/>
      <geometry>
        <cylinder radius="0.0015" length="0.02"/>
      </geometry>
    </visual>
    <collision>
      <origin xyz="0.01 0 0" rpy="3.141593 1.570793 3.141593"/>
      <geometry>
        <cylinder radius="0.0015" length="0.02"/>
      </geometry>
    </collision>
    <visual>
      <origin xyz="-0.0015 0 0" rpy="3.141593 1.570793 3.141593"/>
      <geometry>
        <cylinder radius="0.0025" length="0.003"/>
      </geometry>
    </visual>
    <collision>
      <origin xyz="-0.0015 0 0" rpy="3.141593 1.570793 3.141593"/>
      <geometry>
        <cylinder radius="0.0025" length="0.003"/>
      </geometry>
    </collision>
  </link>
  <joint name="lidar_screw1_joint" type="fixed">
    <parent link="lidar"/>
    <child link="screw1"/>
    <origin xyz="0.035 0.0245 -0.0105" rpy="0 1.570787 0"/>
  </joint>
  <link name="screw0">
    <visual>
      <origin xyz="0.01 0 0" rpy="3.141593 1.570793 3.141593"/>
      <geometry>
        <cylinder radius="0.0015" length="0.02"/>
      </geometry>
    </visual>
    <collision>
      <origin xyz="0.01 0 0" rpy="3.141593 1.570793 3.141593"/>
      <geometry>
        <cylinder radius="0.0015" length="0.02"/>
      </geometry>
    </collision>
    <visual>
      <origin xyz="-0.0015 0 0" rpy="3.141593 1.570793 3.141593"/>
      <geometry>
        <cylinder radius="0.0025" length="0.003"/>
      </geometry>
    </visual>
    <collision>
      <origin xyz="-0.0015 0 0" rpy="3.141593 1.570793 3.141593"/>
      <geometry>
        <cylinder radius="0.0025" length="0.003"/>
      </geometry>
    </collision>
  </link>
  <joint name="lidar_screw0_joint" type="fixed">
    <parent link="lidar"/>
    <child link="screw0"/>
    <origin xyz="0.035 0.0245 -0.0105" rpy="0 1.570787 0"/>
  </joint>
  <joint name="lidar_secondary_motor" type="continuous">
    <parent link="lidar"/>
    <child link="solid"/>
    <axis xyz="0 -0.000004 1"/>
    <limit effort="10" velocity="150"/>
    <origin xyz="-0.046 0.01 -0.01" rpy="-0.000014 0.000005 3.141587"/>
  </joint>
  <link name="solid">
  </link>
  <joint name="lidar_main_motor" type="continuous">
    <parent link="lidar"/>
    <child link="lower"/>
    <axis xyz="0 -0.000004 1"/>
    <limit effort="10" velocity="40"/>
    <origin xyz="-0.046 0.02 -0.01" rpy="-0.000014 0.000005 3.141587"/>
  </joint>
  <link name="lower">
  </link>
  <link name="camera">
    <visual>
      <origin xyz="0.006 0.01 0.034" rpy="0 0 0"/>
      <geometry>
        <box size="0.04 0.165 0.029"/>
      </geometry>
    </visual>
    <collision>
      <origin xyz="0.006 0.01 0.034" rpy="0 0 0"/>
      <geometry>
        <box size="0.04 0.165 0.029"/>
      </geometry>
    </collision>
    <visual>
      <origin xyz="-0.009 0.01 0.007" rpy="0 0 0"/>
      <geometry>
        <box size="0.061 0.06 0.014"/>
      </geometry>
    </visual>
    <collision>
      <origin xyz="-0.009 0.01 0.007" rpy="0 0 0"/>
      <geometry>
        <box size="0.061 0.06 0.014"/>
      </geometry>
    </collision>
  </link>
  <joint name="base_link_camera_joint" type="fixed">
    <parent link="base_link"/>
    <child link="camera"/>
    <origin xyz="0.1 0.01 0.059" rpy="0 0 0"/>
  </joint>
  <link name="camera depth">
  </link>
  <joint name="camera_camera depth_joint" type="fixed">
    <parent link="camera"/>
    <child link="camera depth"/>
    <origin xyz="0.027 0.037 0.034" rpy="0 0 0"/>
  </joint>
  <link name="camera rgb">
  </link>
  <joint name="camera_camera rgb_joint" type="fixed">
    <parent link="camera"/>
    <child link="camera rgb"/>
    <origin xyz="0.027 0.011 0.034" rpy="-1.570796 0 -1.570796"/>
  </joint>
</robot>
